<?xml version="1.0"?>
<robot name="simple_robot">
    <link name="base_link">
        <visual>
            <origin xyz="0.0 0.0 0.0" rpy="0.0 0.0 0.0"/>
            
            <geometry>
                <cylinder radius="0.2" length="0.05"/>
            </geometry>

            <material name="yellow">
                <color rgba="1.0 1.0 0.0 1.0"/>
            </material>
        </visual>
    </link>

    <joint name="joint_1" type="prismatic">
        <origin xyz="0.0 0.0 0.025" rpy="0.0 0.0 0.0"/>
        <parent link="base_link"/>
        <child link="first_link"/>
        <axis xyz="0.0 0.0 1.0"/> <!-- robot rotates along z-axis -->
        <limit lower="-1.2" upper="1.2" effort="300.0" velocity="2.0"/>
    </joint>

    <link name="first_link">
        <visual>
            <origin xyz="0.0 0.0 0.25" rpy="0.0 0.0 0.0"/>
            <geometry>
                <cylinder radius="0.04" length="0.5"/>
            </geometry>
            <material name="blue">
                <color rgba="0.0 0.0 1.0 1.0"/>
            </material>
        </visual>
    </link>

    <joint name="joint_2" type="prismatic">
        <origin xyz="0.0 0.0 0.5" rpy="0.0 0.0 0.0"/>
        <parent link="first_link"/>
        <child link="second_link"/>
        <axis xyz="0.0 1.0 0.0"/>
        <limit lower="-0.5" upper="0.5" effort="300.0" velocity="2.0"/>
    </joint>

    <link name="second_link">
        <visual>
            <origin xyz="0.0 0.0 0.05" rpy="0.0 0.0 0.0"/>
            <geometry>
                <box size="0.1 1.0 0.1"/>
            </geometry>
            <material name="green">
                <color rgba="0.0 1.0 0.0 1.0"/>
            </material>
        </visual>
    </link>
</robot>